<mujoco model="marrtino_arm">
    <custom>
        <numeric name="ndims" size="1" data="3"/>
        <numeric name="njoints" size="1" data="5"/>
    </custom>    

	<compiler angle="radian" inertiafromgeom="true"/>
    
    <default>
		<joint armature="1" damping="1" limited="true"/>
		<geom contype="0" friction="1 0.1 0.1" rgba="0.7 0.7 0 1"/>
	</default>
    
    <option gravity="0 0 -9.81" integrator="RK4" timestep="0.01"/>

    <asset>
      <texture name="grid" type="2d" builtin="checker" rgb1=".6 .6 .6"
        rgb2=".8 .8 .8" width="100" height="100" mark="edge" markrgb="0.4 0.4 0.4"/>
      <material name="grid" texture="grid" texrepeat="10 10" texuniform="true"
        reflectance="0"/>
    </asset>

    
    <worldbody>
    
   	    <light name="top1" pos="0.5 0.5 1"/>
	    <light name="top2" pos="-0.5 0.5 1"/>
	    <light name="top3" pos="0.5 -0.5 1"/>
	    <light name="top4" pos="-0.5 -0.5 1"/>

		<!-- Arena -->
		<geom type="plane" conaffinity="1" contype="1" name="ground" pos="0.05 0.05 0" rgba="0.98 0.98 0.98 1" size="1 1 10"  material="grid"/>

		<!-- Arm -->
		<geom conaffinity="1" contype="1" fromto="0 0 0 0 0 0.09" name="root" rgba="0.9 0.4 0.6 1" size=".011" type="cylinder"/>
		<body name="base" pos="0 0 .091">
			<geom fromto="0 0 0 0 0 0.045" name="link0" rgba="0.0 0.4 0.6 1" size=".01" type="capsule"/>
			<joint axis="0 0 1" limited="true" range="-1.5707963267948966 1.5707963267948966" name="j0" pos="0 0 0" type="hinge"/>
            <geom fromto="0 0 0 0 0 0.01" name="jcolor0" rgba="0.0 0.0 1.0 0.5" size=".013" type="capsule"/>
            
            <body name="j0" pos="0 0 0.045">
				<geom fromto="0 0 0 0 0 0.11" name="link1" rgba="0.0 0.4 0.6 1" size=".01" type="capsule"/>
                <joint axis="0 1 0" limited="true" range="-1.5707963267948966 1.5707963267948966" name="j1" pos="0 0 0" type="hinge"/>
                <geom fromto="0 0 0 0 0 0.01" name="jcolor1" rgba="0.0 1.0 0.0 1" size=".012" type="capsule"/>
                
                <body name="j1" pos="0 0 0.11">
                    <geom fromto="0 0 0 0 0 0.11" name="link2" rgba="0.0 0.4 0.6 1" size=".01" type="capsule"/>
                    <joint axis="0 1 0" limited="true" range="-1.5707963267948966 1.5707963267948966" name="j2" pos="0 0 0" type="hinge"/>    
                    <geom fromto="0 0 0 0 0 0.01" name="jcolor2" rgba="0.0 1.0 0.0 1" size=".012" type="capsule"/>
                    
                    <body name="j2" pos="0 0 0.11">
                        <geom fromto="0 0 0 0 0 0.115" name="link3" rgba="0.0 0.4 0.6 1" size=".01" type="capsule"/>
                        <joint axis="0 1 0" limited="true" range="-1.5707963267948966 1.5707963267948966" name="j3" pos="0 0 0" type="hinge"/>    
                        <geom fromto="0 0 0 0 0 0.01" name="jcolor3" rgba="0.0 1.0 0.0 1" size=".012" type="capsule"/>
                            
                        <body name="j3" pos="0 0 0.115">
                            <geom fromto="0 0 0 0 0 0.12" name="link4" rgba="   0.0 0.4 0.6 1" size=".01" type="capsule"/>
                            <joint axis="1 0 0" limited="true" range="-1.5707963267948966 1.5707963267948966" name="j4" pos="0 0 0" type="hinge"/>    
                            <geom fromto="0 0 0 0 0 0.01" name="jcolor4" rgba="1.0 0.0 0.0 1" size=".012" type="capsule"/>
                            
                            <body name="fingertip" pos="0 0 0.12">
                                <geom contype="0" name="fingertip" pos="0 0 0" rgba="0.99 0.0 0.0 1" size=".020" type="sphere"/>
                            </body>
                        </body>
                    </body>
                </body>
			</body>
        </body>


		<!-- Target -->
		<body name="target" pos="0 0 .0281">
    		<geom conaffinity="1" contype="1" name="target" rgba="1 0.6 0 1" size=".028 0.001" type="sphere"/>
			<joint armature="0" axis="1 0 0" damping="0" limited="false" name="target_x" pos="0 0 0" type="slide"/>
			<joint armature="0" axis="0 1 0" damping="0" limited="false" name="target_y" pos="0 0 0"  type="slide"/>
		</body>

		<!-- Objects -->
		<body name="obstacle1" pos="0 0 0.251" >
            <geom name="obs1" rgba="0.2 0.9 0.9 1" type="cylinder" size="0.02 0.25" density="0.1" contype="1" conaffinity="1" />
            <joint name="obs1_x" type="slide" pos="0 0 0" axis="1 0 0" range="-0.6 0.6" stiffness="0" damping="0" frictionloss="0.001" armature="0" />
            <joint name="obs1_y" type="slide" pos="0 0 0" axis="0 1 0" range="-0.6 0.6" stiffness="0" damping="0" frictionloss="0.001" armature="0" />
        </body>

		<body name="obstacle2" pos="0 0 0.251" >
            <geom name="obs2" rgba="0.2 0.9 0.9 1" type="cylinder" size="0.02 0.25" density="0.1" contype="1" conaffinity="1" />
            <joint name="obs2_x" type="slide" pos="0 0 0" axis="1 0 0" range="-0.6 0.6" stiffness="0" damping="0" frictionloss="0.001" armature="0" />
            <joint name="obs2_y" type="slide" pos="0 0 0" axis="0 1 0" range="-0.6 0.6" stiffness="0" damping="0" frictionloss="0.001" armature="0" />
        </body>

		<body name="obstacle3" pos="0 0 0.251" >
            <geom name="obs3" type="cylinder" rgba="0.2 0.9 0.9 1" size="0.02 0.25" density="0.1" contype="1" conaffinity="1" />
            <joint type="slide" name="obs3_x" pos="0 0 0" axis="1 0 0" range="-0.6 0.6" stiffness="0" damping="0" frictionloss="0.001" armature="0" />
            <joint type="slide" name="obs3_y" pos="0 0 0" axis="0 1 0" range="-0.6 0.6" stiffness="0" damping="0" frictionloss="0.001" armature="0" />
        </body>


		<!-- Ball --
		<body name="ball" pos="0 0 0.0251" gravcomp="1">
			<joint armature="0" axis="1 0 0" damping="0" limited="false" name="ball_x" pos="0 0 0" range="-.5 .5" type="slide" frictionloss="0.1"/>
			<joint armature="0" axis="0 1 0" damping="0" limited="false" name="ball_y" pos="0 0 0" range="-.5 .5" type="slide" frictionloss="0.1"/>
			<geom conaffinity="1" contype="1" name="ball" pos="0 0 0" rgba="1.0 0.6 0.0 1" size=".025" type="sphere"/>
		</body -->


	</worldbody>
    
    <actuator>
		<motor ctrllimited="true" ctrlrange="-1.0 1.0" gear="200.0" joint="j0"/>
		<motor ctrllimited="true" ctrlrange="-1.0 1.0" gear="200.0" joint="j1"/>
		<motor ctrllimited="true" ctrlrange="-1.0 1.0" gear="200.0" joint="j2"/>
		<motor ctrllimited="true" ctrlrange="-1.0 1.0" gear="200.0" joint="j3"/>
		<motor ctrllimited="true" ctrlrange="-1.0 1.0" gear="200.0" joint="j4"/>
	</actuator>
</mujoco>
