<mujoco model="reacher3">
	<compiler angle="radian" inertiafromgeom="true"/>
	<default>
		<joint armature="1" damping="1" limited="true"/>
		<geom condim="1" contype="0" friction="0.1 0.001 0.001" rgba="0.7 0.7 0 1" density="1.0" />
	</default>
	<option gravity="0 0 -9.81" integrator="RK4" timestep="0.005"/>
	
    <asset>
      <texture name="grid" type="2d" builtin="checker" rgb1=".6 .6 .6"
        rgb2=".8 .8 .8" width="100" height="100" mark="edge" markrgb="0.4 0.4 0.4"/>
      <material name="grid" texture="grid" texrepeat="10 10" texuniform="true"
        reflectance="0"/>
    </asset>

	<worldbody>
	
	    <light name="top1" pos="0.5 0.5 1"/>
	    <light name="top2" pos="-0.5 0.5 1"/>
	    <light name="top3" pos="0.5 -0.5 1"/>
	    <light name="top4" pos="-0.5 -0.5 1"/>

		<!-- Arena -->
		<geom type="plane" name="ground" pos="0.05 0.05 0" rgba="0.99 0.99 0.99 1" size="0.6 0.6 1"  material="grid" conaffinity="0" contype="0" />
		<geom conaffinity="0" fromto="-.45 -.45 .01 .45 -.45 .01" name="sideS" rgba="0.9 0.4 0.6 1" size=".02" type="capsule"/>
		<geom conaffinity="0" fromto=" .45 -.45 .01 .45  .45 .01" name="sideE" rgba="0.9 0.4 0.6 1" size=".02" type="capsule"/>
		<geom conaffinity="0" fromto="-.45  .45 .01 .45  .45 .01" name="sideN" rgba="0.9 0.4 0.6 1" size=".02" type="capsule"/>
		<geom conaffinity="0" fromto="-.45 -.45 .01 -.45 .45 .01" name="sideW" rgba="0.9 0.4 0.6 1" size=".02" type="capsule"/>
		
		<!-- Arm -->
		<geom fromto="0 0 0 0 0 0.025" name="root" rgba="0.9 0.4 0.6 1" size=".011" type="cylinder" conaffinity="1" contype="1" />
		<body name="body0" pos="0 0 .015">
			<geom fromto="0 0 0 0.1 0 0" name="link0" rgba="0.0 0.4 0.6 1" size=".01" type="capsule" conaffinity="1" contype="1" />
			<joint axis="0 0 1" limited="true" name="joint0" pos="0 0 0" range="-3.14 3.14" type="hinge" stiffness="0.01" />
			<body name="body1" pos="0.1 0 0">
				<joint axis="0 0 1" limited="true" name="joint1" pos="0 0 0" range="-1.8 1.8" type="hinge" stiffness="0.01"/>
				<geom fromto="0 0 0 0.1 0 0" name="link1" rgba="0.0 0.4 0.6 1" size=".01" type="capsule" conaffinity="1" contype="1" />
			    <body name="body2" pos="0.1 0 0">
				    <joint axis="0 0 1" limited="true" name="joint2" pos="0 0 0" range="-1.8 1.8" type="hinge" stiffness="0.01" />
				    <geom fromto="0 0 0 0.1 0 0" name="link2" rgba="0.0 0.4 0.6 1" size=".01" type="capsule" conaffinity="1" contype="1" />
				    <body name="fingertip" pos="0.11 0 0">
					    <geom name="fingertip" pos="0 0 0" rgba="0.0 0.8 0.6 1" size=".01" type="sphere" conaffinity="1" contype="1" friction="10.0 0.1 0.1" density="10"/>
				    </body>
    			</body>
			</body>
		</body>
		
		<!-- Target -->
		<body name="target" pos="0 0 .001">
    		<geom conaffinity="0" contype="0" name="target" rgba="0.9 0.2 0.2 1" size=".02 0.001" type="cylinder"/>
			<joint armature="0" axis="1 0 0" damping="0" limited="true" name="target_x" pos="0 0 0" range="-.37 .37" ref="0" stiffness="0" type="slide"/>
			<joint armature="0" axis="0 1 0" damping="0" limited="true" name="target_y" pos="0 0 0" range="-.37 .37" ref="0" stiffness="0" type="slide"/>		
		</body>


		<!-- Objects -->
		<body name="obstacle1" pos="0 0 0.02" >
            <geom type="cylinder" name="obs1" rgba="0.2 0.9 0.9 1"  size="0.02 0.02" density="0.1" contype="1" conaffinity="1" />
            <!-- joint name="jobs" type="free" stiffness="0" damping="0" frictionloss="0" armature="0"/ -->
            <joint type="slide" name="obs1_x" pos="0 0 0" axis="1 0 0" range="-0.4 0.4" stiffness="0" damping="0" frictionloss="0.001" armature="0" />
            <joint type="slide" name="obs1_y" pos="0 0 0" axis="0 1 0" range="-0.4 0.4" stiffness="0" damping="0" frictionloss="0.001" armature="0" />
        </body>

		<body name="obstacle2" pos="0 0 0.02" >
            <geom type="cylinder" name="obs2" rgba="0.2 0.9 0.9 1" size="0.02 0.02" density="0.1" contype="1" conaffinity="1" />
            <joint type="slide" name="obs2_x" pos="0 0 0" axis="1 0 0" range="-0.4 0.4" stiffness="0" damping="0" frictionloss="0.001" armature="0" />
            <joint type="slide" name="obs2_y" pos="0 0 0" axis="0 1 0" range="-0.4 0.4" stiffness="0" damping="0" frictionloss="0.001" armature="0" />
        </body>

		<body name="obstacle3" pos="0 0 0.02" >
            <geom type="cylinder" name="obs3" rgba="0.2 0.9 0.9 1" size="0.02 0.02" density="0.1" contype="1" conaffinity="1" />
            <joint type="slide" name="obs3_x" pos="0 0 0" axis="1 0 0" range="-0.4 0.4" stiffness="0" damping="0" frictionloss="0.001" armature="0" />
            <joint type="slide" name="obs3_y" pos="0 0 0" axis="0 1 0" range="-0.4 0.4" stiffness="0" damping="0" frictionloss="0.001" armature="0" />
        </body>


	</worldbody>

	<actuator>
		<motor ctrllimited="true" ctrlrange="-1.0 1.0" gear="200.0" joint="joint0"/>
		<motor ctrllimited="true" ctrlrange="-1.0 1.0" gear="200.0" joint="joint1"/>
		<motor ctrllimited="true" ctrlrange="-1.0 1.0" gear="200.0" joint="joint2"/>
	</actuator>

	<contact>
		<pair geom1="link0" geom2="obs1" />
		<pair geom1="link0" geom2="obs2" />
		<pair geom1="link0" geom2="obs3" />
		<pair geom1="link1" geom2="obs1" />
		<pair geom1="link1" geom2="obs2" />
		<pair geom1="link1" geom2="obs3" />
		<pair geom1="link2" geom2="obs1" />
		<pair geom1="link2" geom2="obs2" />
		<pair geom1="link2" geom2="obs3" />
		<pair geom1="fingertip" geom2="obs1" />
		<pair geom1="fingertip" geom2="obs2" />
		<pair geom1="fingertip" geom2="obs3" />
	</contact>

</mujoco>
