<mujoco model="reacher">
	<compiler angle="radian" inertiafromgeom="true"/>
	<default>
		<joint armature="1" damping="1" limited="true"/>
		<geom condim="1" contype="0" friction="0.1 0.001 0.001" rgba="0.7 0.7 0 1"/>
	</default>
	<option gravity="0 0 -9.81" integrator="RK4" timestep="0.01"/>
	
	<asset>
      <texture name="grid" type="2d" builtin="checker" rgb1=".6 .6 .6"
        rgb2=".8 .8 .8" width="100" height="100" mark="edge" markrgb="0.4 0.4 0.4"/>
      <material name="grid" texture="grid" texrepeat="10 10" texuniform="true"
        reflectance="0"/>
    </asset>
	
	
	<worldbody>

	    <light name="top1" pos="0.5 0.5 1"/>
	    <light name="top2" pos="-0.5 0.5 1"/>
	    <light name="top3" pos="0.5 -0.5 1"/>
	    <light name="top4" pos="-0.5 -0.5 1"/>
		
		<!-- Arena -->
		<geom type="plane" name="ground" pos="0.05 0.05 0" rgba="0.99 0.99 0.99 1" size="0.6 0.6 1"  material="grid" conaffinity="0" contype="0" />
		<geom conaffinity="0" fromto="-.35 -.35 .01 .35 -.35 .01" name="sideS" rgba="0.9 0.4 0.6 1" size=".02" type="capsule"/>
		<geom conaffinity="0" fromto=" .35 -.35 .01 .35  .35 .01" name="sideE" rgba="0.9 0.4 0.6 1" size=".02" type="capsule"/>
		<geom conaffinity="0" fromto="-.35  .35 .01 .35  .35 .01" name="sideN" rgba="0.9 0.4 0.6 1" size=".02" type="capsule"/>
		<geom conaffinity="0" fromto="-.35 -.35 .01 -.35 .35 .01" name="sideW" rgba="0.9 0.4 0.6 1" size=".02" type="capsule"/>
		
		<!-- Arm -->
		<geom conaffinity="0" contype="0" fromto="0 0 0 0 0 0.02" name="root" rgba="0.9 0.4 0.6 1" size=".011" type="cylinder"/>
		<body name="body0" pos="0 0 .01">
			<geom fromto="0 0 0 0.1 0 0" name="link0" rgba="0.0 0.4 0.6 1" size=".01" type="capsule" contype="1" conaffinity="1" />
			<joint axis="0 0 1" limited="true" name="joint0" pos="0 0 0" range="-3.14 3.14" type="hinge"
                 solreflimit="4e-3 1" solimplimit=".95 .99 1e-3"/>
			<body name="body1" pos="0.1 0 0">
				<joint axis="0 0 1" limited="true" name="joint1" pos="0 0 0" range="-3.0 3.0" type="hinge"
				                 solreflimit="4e-3 1" solimplimit=".95 .99 1e-3"/>
				<geom fromto="0 0 0 0.1 0 0" name="link1" rgba="0.0 0.4 0.6 1" size=".01" type="capsule" contype="1" conaffinity="1" />
				<body name="fingertip" pos="0.11 0 0">
					<geom contype="1" conaffinity="1" name="fingertip" pos="0 0 0" rgba="0.0 0.8 0.6 1" size=".01" type="sphere"/>
				</body>
			</body>
		</body>

		<!-- Target -->
		<body name="target" pos="0 0 .001">
    		<geom conaffinity="0" contype="0" name="target" rgba="0.9 0.2 0.2 1" size=".02 0.001" type="cylinder"/>
			<joint armature="0" axis="1 0 0" damping="0" limited="true" name="target_x" pos="0 0 0" range="-.3 .3" ref="0" stiffness="0" type="slide"/>
			<joint armature="0" axis="0 1 0" damping="0" limited="true" name="target_y" pos="0 0 0" range="-.3 .3" ref="0" stiffness="0" type="slide"/>		
		</body>
		
		<!-- Objects -->
		<body name="obstacle1" pos="0 0 0.02" >
            <geom rgba="0.2 0.9 0.9 1" type="cylinder" size="0.02 0.02" density="0.1" contype="1" conaffinity="1" />
            <joint name="obs1_x" type="slide" pos="0 0 0" axis="1 0 0" range="-0.3 0.3" stiffness="0" damping="0" frictionloss="0.001" armature="0" />
            <joint name="obs1_y" type="slide" pos="0 0 0" axis="0 1 0" range="-0.3 0.3" stiffness="0" damping="0" frictionloss="0.001" armature="0" />
        </body>

		<body name="obstacle2" pos="0 0 0.02" >
            <geom rgba="0.2 0.9 0.9 1" type="cylinder" size="0.02 0.02" density="0.1" contype="1" conaffinity="1" />
            <joint name="obs2_x" type="slide" pos="0 0 0" axis="1 0 0" range="-0.3 0.3" stiffness="0" damping="0" frictionloss="0.001" armature="0" />
            <joint name="obs2_y" type="slide" pos="0 0 0" axis="0 1 0" range="-0.3 0.3" stiffness="0" damping="0" frictionloss="0.001" armature="0" />
        </body>

		<body name="obstacle3" pos="0 0 0.02" >
            <geom type="cylinder" name="obs3" rgba="0.2 0.9 0.9 1" size="0.02 0.02" density="0.1" contype="1" conaffinity="1" />
            <joint type="slide" name="obs3_x" pos="0 0 0" axis="1 0 0" range="-0.4 0.4" stiffness="0" damping="0" frictionloss="0.001" armature="0" />
            <joint type="slide" name="obs3_y" pos="0 0 0" axis="0 1 0" range="-0.4 0.4" stiffness="0" damping="0" frictionloss="0.001" armature="0" />
        </body>

	</worldbody>
	<actuator>
		<motor ctrllimited="true" ctrlrange="-1.0 1.0" gear="200.0" joint="joint0"/>
		<motor ctrllimited="true" ctrlrange="-1.0 1.0" gear="200.0" joint="joint1"/>
	</actuator>
</mujoco>
